Workbook
Name _1.전기공사: #REF!
Name _1.전기공사: #REF!
Name _A100000: #REF!
Name _A100000: #REF!
Name _A66000: #REF!
Name _A66000: #REF!
Name _A67000: #REF!
Name _A67000: #REF!
Name _A68000: #REF!
Name _A68000: #REF!
Name _A80000: #REF!
Name _A80000: #REF!
Name _zz1: #REF!
Name _zz1: #REF!
Name 가맹: #REF!
Name 가맹: #REF!
Name 가설공: #REF!
Name 가설공: #REF!
Name 가시설: #REF!
Name 가시설: #REF!
Name 감사..: #REF!
Name 감사..: #REF!
Name 갑지: #REF!
Name 갑지: #REF!
Name 건물용도: #REF!
Name 건물용도: #REF!
Name 건축: #REF!
Name 건축: #REF!
Name 경과년수: #REF!
Name 계측기: #REF!,#REF!
Name 계측기: #REF!,#REF!
Name 고급: #REF!
Name 고급: #REF!
Name 고케: 70455
Name 공사명: #REF!
Name 공사명: #REF!
Name 공정수량: #REF!
Name 공정수량: #REF!
Name 공정집계: #REF!
Name 공정집계: #REF!
Name 공조실급수2: #REF!
Name 공조실급수2: #REF!
Name 구구일일: #REF!
Name 구조방식: #REF!
Name 구조방식: #REF!
Name 구조형식: #REF!
Name 구조형식: #REF!
Name 근린합계: #REF!
Name 근린합계: #REF!
Name 기술료: #REF!
Name 기술료: #REF!
Name 기술사: #REF!
Name 기술사: #REF!
Name 기초대가: #REF!
Name 기초대가: #REF!
Name 내선: 49296
Name 내업: #REF!
Name 내업: #REF!
Name 내역: #REF!
Name 내역: #REF!

Sheet 갑지
B1: ㈜ 에 이 앤 비
B3: (우) 16910 경기도 용인시 기흥구 마북로 159 (마북동) 전화: 031-283-3328 팩스: 031-284-3328
B6: 문서번호 : | F6: ANB-20260219-9
B7: 작성일자 : | F7: 46072
B8: 수 신 : | F8: 효성뉴서울5차아파트 | N8: 입주자대표회의
B9: 참 조 : | F9: 관리소장
B10: 제 목 : | F10: 하자점검(조사)
B14: 1. 귀 아파트(사)의 무궁한 발전을 기원합니다.
B16: 2. 당 사는 경기도 용인시 기흥구 마북로 159, 한성프라자 207호에 위치한 업체로 시설물 안전진단(구조 안전진단), 안전점검(정밀, 정기), 건축물 하자점검(조사), 장기수선계획 조정(검토 포함), 시설물 유지보수(도장, 방수공사 등), 보수공사 감리, 기술자문 등을 주 업무로 하는 ㈜에이앤비입니다.
B18: 3. 귀 아파트(사)에서 의뢰하신 하자점검(조사) 건에 대한 견적서를 제출하오니 업무에 참고하시기 바랍니다.
B20: 4. 시설물 개요
F21: 가. 조 사 대 상 : | L21: =F8 -> 효성뉴서울5차아파트
F22: 나. 점 검 범 위 : | L22: 아파트 6개동 648세대 (해당동 : 6개동)
F23: 다. 소 재 지 : | L23: 인천 계양구 아나지로 199 (효성동)
F24: 라. 준 공 일 : | L24: 1994년 12월
F25: 마. 전화 / 팩스 :
B27: 5. 용역의 범위
F28: 가.「공동주택관리법」(이하 “공주법”이라 한다) 제6장 하자담보책임의 제36. 37조
F29: 나. 보고서 제출 3부
B31: 6. 용 역 비 : | L31: =대가산출!D3 -> 일금일백팔십만원정 (₩1,800,000)-VAT별도
B33: 7. 특이사항
B36: ※첨 부 : 1. 견적서 1부 끝.
B38: ㈜에이앤비 대표이사

Sheet 대가산출
B1: 하자점검(조사) 용역
B3: 총 용 역 비 | D3: ="일금"&NUMBERSTRING(H29,1)&"원정 ("&DOLLAR(H29,0)&")-VAT별도" -> 일금일백팔십만원정 (₩1,800,000)-VAT별도
B4: 공급가액 | D4: ="일금 "&NUMBERSTRING(H29,1)&"원정"&TEXT(H29,"(￦ #,##0)")&" " -> 일금 일백팔십만원정(₩ 1,800,000)
B5: 부가가치세 | D5: ="일금 "&NUMBERSTRING(H30,1)&"원정"&TEXT(H30,"(￦ #,##0)")&" " -> #VALUE!
B6: 산 출 내 역 서
B7: 구 분 | D7: 기술자등급 | E7: 단 위 | F7: 인 원 | G7: 단 가 | H7: 금 액 | I7: 비 고
B8: 1. 직 접 인 건 비 | H8: =INT(SUM(H9,H10,H11,H12,H13,H14,H15,H16)) -> 1328145 | I8: 인원은 변경될수 있음
C9: 가. 외업 | D9: 특급기술자 | E9: 인·일 | F9: 0 | G9: 373353 | H9: =G9*F9 -> 0
D10: 고급기술자 | E10: 인·일 | F10: 1 | G10: 310884 | H10: =G10*F10 -> 310884
D11: 중급기술자 | E11: 인·일 | F11: 0 | G11: 295138 | H11: =G11*F11 -> 0
D12: 초급기술자 | E12: 인·일 | F12: 1 | G12: 235459 | H12: =G12*F12 -> 235459
C13: 나. 내업 | D13: 특급기술자 | E13: 인·일 | F13: 0 | G13: 373353 | H13: =G13*F13 -> 0
D14: 고급기술자 | E14: 인·일 | F14: 1 | G14: 310884 | H14: =G14*F14 -> 310884
D15: 중급기술자 | E15: 인·일 | F15: 0 | G15: 295138 | H15: =G15*F15 -> 0
D16: 초급기술자 | E16: 인·일 | F16: 2 | G16: 235459 | H16: =G16*F16 -> 470918
B17: 2. 제 경 비 | E17: % | F17: 10 | H17: =ROUND(H8*F17%, 0) -> 132815 | I17: 직접인건비 * 10%
B18: 3. 기 술 료 | E18: % | F18: 10 | H18: =ROUND((H8+H17)*F18%, 0) -> 146096 | I18: (직접인건비 + 제경비) * 10%
B19: 4. 직 접 경 비 | H19: =INT(SUM(H21,H22,H23,H24,H25,)) -> 231041
B20: 가. 체재비 및 차량비
B21: (1) 여비 및 현장체재비 | E21: 1 | F21: 2 | G21: 20000 | H21: =G21*F21 -> 40000
B22: (2) 차량운행비 | E22: 1 | F22: 2 | G22: 20000 | H22: =G22*F22 -> 40000
B23: (3) 위험수당 | E23: % | F23: 10 | H23: =ROUND((SUM(H9:H12))*F23%, 0) -> 54634 | I23: 외업인건비의 10%
B24: (4) 기계기구손료 | E24: % | F24: 5 | H24: =ROUND(H8*F24%, 0) -> 66407 | I24: 직접인건비의 5%
B25: (5) 인쇄비 | E25: 식 | F25: 1 | G25: 30000 | H25: =G25*F25 -> 30000
B26: 5. 조 정 비 | H26: =INT(SUM(H8,H17,H18,H19)*0) -> 0 | I26: 구조형식,용도,경과년수
B27: 6. 합 계 금 액 | D27: ( 1 + 2 + 3 + 4 ) | H27: =H8+H17+H18+H19 -> 1838097
B28: 절 삭 금 액 | H28: 38097
B29: 공 급 가 액 | H29: =H27-H28 -> 1800000
B30: 부가가치세 | H30: 별도
B31: 견 적 금 액 | H31: =H29 -> 1800000 | I31: 부가세 별도
D32: ㈜ 에 이 앤 비
D33: 사업자등록번호 : 863-87-00907 | I33: ※ 특이사항
D34: 경기도 용인시 기흥구 마북로 159 (한성프라자 207호) | I34: 견적서 유효기간
D35: 대 표 이 사 서 응 원 (인) | I35: 발행일로부터
D36: 전화번호 : 031-283-3328 담당자 : 이 현 희 실장 | I36: 30일입니다.

Sheet 계약서1
B7: 사우
B8: 하자점검(조사) 용역 계약서
B9: =갑지!F8 -> 효성뉴서울5차아파트
B16: =갑지!F7 -> 46072
B22: 사우
I23: ㈜ 에이앤비
I24: 경기도 용인시 기흥구 마북로 159 한성프라자 207호
I25: 전화 : 031-283-3328 팩스 :031-284-3328
B28: 하자점검(조사) 표준계약서
B29: 계 약 자 | D29: 관 리 주 체 | G29: =B9 -> 효성뉴서울5차아파트
D30: 계약상대자 | G30: ● 상호또는법인명 : (주)에이앤비
G31: ● 사업자등록번호 : 863-87-00907
G32: ● 주 소 : 경기도 용인시 기흥구 마북로 159 한성프라자 207호
G33: ● 전화번호 : 031-283-3328 팩스번호 : 031-284-3328
G34: ● 대 표 자 : 서 응 원
B35: 계 약 내 용 | D35: 계 약 건 명 | G35: =G29 -> 효성뉴서울5차아파트 | M35: 하자점검(조사) 용역
D36: 계 약 금 액 | G36: =갑지!L31 -> 일금일백팔십만원정 (₩1,800,000)-VAT별도
D37: 공 급 가 액 | G37: =갑지!L31 -> 일금일백팔십만원정 (₩1,800,000)-VAT별도
D38: 부가 가치세 | G38: 10% 별도
D39: 계 약 기 간 | G39: 2026 . . . ~ 2026 . . .
D40: 위 치 | G40: =갑지!L23 -> 인천 계양구 아나지로 199 (효성동)
G41: 전화 : | N41: / | O41: 팩스 :
D42: 보고서 납품 | G42: 하자점검(조사)보고서 3부
D43: 기 타 사 항 | G43: 상기 금액은 하자점검(조사) 용역대가임.
B45: 관리주체와 계약상대자는 상호 대등한 입장에서 붙임의 계약문서에 의하여 위와 같이 계약을 체결하고 신의에 따라 성실히 계약상의 의무를 이행할 것을 확약하며, 이 계약의 증거로서 계약서를 작성하여 당사자가 기명날인한 후 각각 1통씩 보관한다.
B47: 붙 임 서 류 : | E47: 1. 하자점검(조사) 표준계약조건 1부.
B51: 계 약 일 자 : | E51: 2026년 월 일
B52: 관 리 주 체(발 주 자) | L52: 계 약 상 대 자(수 주 자)
B53: 상 호 : | E53: =G29 -> 효성뉴서울5차아파트 | L53: 상 호 : | O53: ㈜ 에 이 앤 비
B54: 주 소 : | E54: =G40 -> 인천 계양구 아나지로 199 (효성동) | L54: 주 소 : | O54: 경기도 용인시 기흥구 마북로 159 한성프라자 207호
B55: 관리소장 : | E55: (인) | L55: 대표이사 : | O55: 서 응 원 (인)
B56: <붙임 1>
B57: 하 자 점 검(조사) 표 준 계 약 조 건
B59: 「공동주택관리법」(이하 “공주법”이라 한다) 제6장 하자담보책임 제36조(하자담보책임)과 제37조(하자보수 등), 시행령 제36조(담보책임기간)과 제37조(하자의 범위)의 규정에 따라
B60: =E53 -> 효성뉴서울5차아파트 | J60: (이하 "발주자"라 한다)와 하자점검(조사)의 실시자인
B61: ㈜에이앤비(이하 "수주자"라 한다)는 다음과 같이 계약을 체결한다.
B63: 제1조(목적)
C64: 이 계약은 "발주자"가 관리하고 있는 시설물에 대하여 "수주자"는 하자 점검(조사) 을 실시하고 그에 대한 신속하고 적절한 조치를 취하기 위하여 조사・측정・평가하고 보수・보강 등의 방법을 제시함으로써 재해 및 재난을 예방하고 시설물의 효용증진과 공공의 안전을 확보하는데 그 목적이 있다.
B66: 제2조 (하자점검(조사))의 범위
C67: ① 시설물명 : | F67: =E53 -> 효성뉴서울5차아파트
...
