Workbook
Name _1.전기공사: #REF!
Name _1.전기공사: #REF!
Name _A100000: #REF!
Name _A100000: #REF!
Name _A66000: #REF!
Name _A66000: #REF!
Name _A67000: #REF!
Name _A67000: #REF!
Name _A68000: #REF!
Name _A68000: #REF!
Name _A80000: #REF!
Name _A80000: #REF!
Name _zz1: #REF!
Name _zz1: #REF!
Name 가맹: #REF!
Name 가맹: #REF!
Name 가설공: #REF!
Name 가설공: #REF!
Name 가시설: #REF!
Name 가시설: #REF!
Name 감사..: #REF!
Name 감사..: #REF!
Name 갑지: #REF!
Name 갑지: #REF!
Name 건물용도: #REF!
Name 건물용도: #REF!
Name 건축: #REF!
Name 건축: #REF!
Name 경과년수: #REF!
Name 계측기: #REF!,#REF!
Name 계측기: #REF!,#REF!
Name 계측기: #REF!,#REF!
Name 고급: #REF!
Name 고급: #REF!
Name 고케: 70455
Name 공사명: #REF!
Name 공사명: #REF!
Name 공정수량: #REF!
Name 공정수량: #REF!
Name 공정집계: #REF!
Name 공정집계: #REF!
Name 공조실급수2: #REF!
Name 공조실급수2: #REF!
Name 구구일일: #REF!
Name 구조방식: #REF!
Name 구조방식: #REF!
Name 구조형식: #REF!
Name 구조형식: #REF!
Name 근린합계: #REF!
Name 근린합계: #REF!
Name 기술료: #REF!
Name 기술사: #REF!
Name 기초대가: #REF!
Name 기초대가: #REF!
Name 내선: 49296
Name 내업: #REF!
Name 내업: #REF!
Name 내역: #REF!
Name 내역: #REF!
Name 내역111111111111111: #REF!

Sheet 갑지
D1: ㈜ 에 이 앤 비
D3: (우)16910 경기도 용인시 기흥구 마북로 159 한성프라자 207호 (마북동) 전화 : 031-283-3328 팩스 : 031-284-3328
D6: 문서번호 : | H6: ANB-20260219-9
D7: 작성일자 : | H7: 46072
D8: 수 신 : | H8: 효성뉴서울5차아파트
D9: 참 조 : | H9: 관리소장
D10: 제 목 : | H10: 2026년 상반기
D14: 1. 귀 아파트(사)의 무궁한 발전을 기원합니다.
D16: 2. 당 사는 경기도 용인시 기흥구 마북로 159, 한성프라자 207호에 위치한 업체로 시설물 안전진단(구조 안전진단), 안전점검(정밀, 정기), 건축물 하자 조사(점검), 장기수선계획 조정(검토 포함), 시설물 유지보수(도장, 방수공사 등), 기술자문및 감리 등을 주 업무로 하는 ㈜에이앤비입니다.
D18: 3. 귀 아파트(사)에서 의뢰하신 정기안전점검건에 대한 견적서를 제출하오니 업무에 참고하시기 바랍니다.
D20: 4. 시설물 개요
H21: 가. 단 지 명 : | N21: 효성뉴서울5차아파트
H22: 나. 소 재 지 : | N22: 인천 계양구 아나지로 199 (효성동)
H23: 다. 점 검 범 위 : | N23: 아파트 6개동 648세대 (해당동 : 6개동)
H24: 라. 준 공 일 : | N24: 1994년 12월
H25: 마. 전화 / 팩스 : | N25: 031-283-3328 / 031-284-3328
D27: 5. 용역의 범위
H28: 가. 시설물의 안전 및 유지관리에 관한 특별법 제11조에 의거한 건축물 정기안전점검
H29: 나. 정기안전점검 보고서 제출 및 FMS등록
D31: 6. 용 역 비 : | N31: ="일금"&NUMBERSTRING(대가산출!H29,1)&"원정 (₩"&TEXT(대가산출!H29,"#,##0")&")" -> 일금일백오십만원정 (₩1,500,000) | AB31: (VAT별도)
D33: 7. 지 불 조 건 : | N33: 정기안전점검보고서 납품(FMS 등록)후 10일 이내 지불조건
D36: ※ 첨 부 : 1. 견적서 1부 끝.
D38: ㈜에이앤비 대표이사

Sheet 대가산출
B1: 정기안전점검 용역
B3: 총 용 역 비 | D3: ="일금"&NUMBERSTRING(H29,1)&"원정 (₩"&TEXT(H29,"#,##0")&") - VAT별도" -> 일금일백오십만원정 (₩1,500,000) - VAT별도
B4: 공급가액 | D4: ="일금 "&NUMBERSTRING(H29,1)&"원정"&TEXT(H29,"(￦ #,##0)")&" " -> 일금 일백오십만원정(₩ 1,500,000)
B5: 부가가치세 | D5: ="일금 "&NUMBERSTRING(H30,1)&"원정"&TEXT(H30,"(￦ #,##0)")&" "
B6: 산 출 내 역 서
B7: 구 분 | D7: 기술자등급 | E7: 단 가 | F7: 단 위 | G7: 인 원 | H7: 금 액 | I7: 비 고
B8: 1. 직 접 인 건 비 | H8: =INT(SUM(H9,H10,H11,H12,H13,H14,H15,H16)) -> 1092686 | I8: 인원은 변경될수 있음
C9: 가. 외업 | D9: 특급기술자 | E9: 373353 | F9: 인·일 | G9: 0 | H9: =INT(E9*G9) -> 0
D10: 고급기술자 | E10: 310884 | F10: 인·일 | G10: 1 | H10: =INT(E10*G10) -> 310884
D11: 중급기술자 | E11: 295138 | F11: 인·일 | G11: 0 | H11: =INT(E11*G11) -> 0
D12: 초급기술자 | E12: 235459 | F12: 인·일 | G12: 1 | H12: =INT(E12*G12) -> 235459
C13: 나. 내업 | D13: 특급기술자 | E13: 373353 | F13: 인·일 | G13: 0 | H13: =INT(E13*G13) -> 0
D14: 고급기술자 | E14: 310884 | F14: 인·일 | G14: 1 | H14: =INT(E14*G14) -> 310884
D15: 중급기술자 | E15: 295138 | F15: 인·일 | G15: 0 | H15: =INT(E15*G15) -> 0
D16: 초급기술자 | E16: 235459 | F16: 인·일 | G16: 1 | H16: =INT(E16*G16) -> 235459
B17: 2. 제 경 비 | F17: % | G17: 10 | H17: =ROUND(H8*G17%,0) -> 109269 | I17: 직접인건비 * 10%
B18: 3. 기 술 료 | F18: % | G18: 10 | H18: =ROUND((H8+H17)*G18%,0) -> 120196 | I18: (직접인건비+제경비) * 10%
B19: 4. 직 접 경 비 | H19: =INT(SUM(H21,H22,H23,H24,H25,)) -> 219268
B20: 가. 체재비 및 차량비
B21: (1) 여비 및 현장체재비 | E21: 20000 | F21: 1 | G21: 2 | H21: =G21*E21*F21 -> 40000
B22: (2) 차량운행비 | E22: 20000 | F22: 1 | G22: 2 | H22: =G22*E22*F22 -> 40000
B23: (3) 위험수당 | F23: % | G23: 10 | H23: =ROUND((SUM(H9:H12))*G23%,0) -> 54634 | I23: 외업인건비의 10%
B24: (4) 기계기구손료 | F24: % | G24: 5 | H24: =ROUND(H8*G24%,0) -> 54634 | I24: 직접인건비의 5%
B25: (5) 인쇄비 | E25: 30000 | F25: 식 | G25: 1 | H25: =INT(G25*E25) -> 30000
B26: 5. 조 정 비 | H26: =INT(SUM(H8,H17,H18,H19)*0) -> 0 | I26: 구조형식,용도,경과년수
B27: 6. 합 계 금 액 | D27: ( 1 + 2 + 3 + 4 ) | H27: =(SUM(H8,H17,H18,H19,H26)) -> 1541419
B28: 절 삭 금 액 | H28: 41419
B29: 공 급 가 액 | H29: =H27-H28 -> 1500000
B30: 부가가치세 | H30: 별도
B31: 견 적 금 액 | H31: =H29 -> 1500000 | I31: 부가세 별도
D32: ㈜ 에 이 앤 비
D33: 사업자등록번호 : 863-87-00907 | I33: ※ 특이사항
D34: 경기도 용인시 기흥구 마북로 159 (한성프라자 207호) | I34: 견적서 유효기간
D35: 대 표 이 사 서 응 원 (인) | I35: 발행일로부터
D36: 전화번호 : 031-283-3328 담당자 : 이 현 희 실장 | I36: 30일입니다.

Sheet 계약서
B7: 사우
B8: 정기안전점검 용역 계약서
B9: =갑지!H8 -> 효성뉴서울5차아파트
B16: =갑지!H10 -> 2026년 상반기
I22: ㈜ 에이앤비
I23: 경기도 용인시 기흥구 마북로 159 한성프라자 207호
I24: 전화 : 031-283-3328 팩스 :031-284-3328
B27: 시설물의 정기안전점검 표준계약서
B28: 계 약 자 | D28: 관 리 주 체 | G28: =B9 -> 효성뉴서울5차아파트
D29: 계약상대자 | G29: ● 상호 또는 법인명 : (주)에이앤비
G30: ● 사업자등록번호 : 863-87-00907
G31: ● 주 소 : 경기도 용인시 기흥구 마북로 159 한성프라자 207호
G32: ● 전화번호 : 031-283-3328 팩스번호 : 031-284-3328
G33: ● 대 표 자 : 서 응 원
B34: 계 약 내 용 | D34: 계 약 건 명 | G34: =G28&" 정기안전점검 용역" -> 효성뉴서울5차아파트 정기안전점검 용역
D35: 계 약 금 액 | G35: =갑지!N31&" - VAT별도" -> 일금일백오십만원정 (₩1,500,000) - VAT별도
D36: 공 급 가 액 | G36: =G35 -> 일금일백오십만원정 (₩1,500,000) - VAT별도
D37: 부가 가치세 | G37: 10% 별도
D38: 계 약 기 간 | G38: 2026 . . . ~ 2026 . . .
D39: 위 치 | G39: =갑지!N22 -> 인천 계양구 아나지로 199 (효성동)
G40: 전 화 : | I40: 031-283-3328 | N40: / | O40: 팩 스 : | Q40: 031-284-3328
D41: 보고서 납품 | G41: 시설물통합정보시스템(FMS)등록 후 정기안전점검 보고서 1부
D42: 기 타 사 항 | G42: 상기 금액은
B45: 관리주체와 계약상대자는 상호 대등한 입장에서 붙임의 계약문서에 의하여 위와 같이 계약을 체결하고 신의에 따라 성실히 계약상의 의무를 이행할 것을 확약하며, 이 계약의 증거로서 계약서를 작성하여 당사자가 기명날인한 후 각각 1통씩 보관한다.
B47: 붙 임 서 류 : | E47: 1. 시설물의 정기안전점검 표준계약조건 1부.
E48: 2. 시설물의 정기안전점검 과업내용 1부.
E49: 3. 시설물의 정기안전점검 대가산출 내역서 1부.
B51: 계 약 일 자 : | E51: 2026 년 월 일
B52: 관 리 주 체(발 주 자) | L52: 계 약 상 대 자(수 주 자)
B53: 상 호 : | E53: =B9 -> 효성뉴서울5차아파트 | L53: 상 호 : | O53: ㈜ 에 이 앤 비
B54: 주 소 : | E54: =G39 -> 인천 계양구 아나지로 199 (효성동) | L54: 주 소 : | O54: 경기도 용인시 기흥구 마북로 159, 한성프라자 207호(마북동)
B55: 관리소장 : | E55: (인) | L55: 대표이사 : | O55: 서 응 원 (인)
B56: <붙임 1>
B57: 시설물의 정기안전점검 표준계약조건
B59: 「시설물의 안전 및 유지관리에 관한 특별법」(이하 “시설물안전법”이라 한다) 제11조, 제12조 및
B60: 동법 시행령 제8조에 따라 | I60: =B9 -> 효성뉴서울5차아파트 | P60: (이하 "발주자"라 한다)와
B61: 정기안전점검의 실시자인 ㈜에이앤비(이하 "수주자"라 한다)는 다음과 같이 계약을 체결한다.
B63: 제1조(목적)
C64: 이 계약은 "발주자"가 관리하고 있는 시설물에 대하여 "수주자"는 정기안전점검을 실시하여 구조적・기능적 결함을 발견하고, 그에 대한 신속하고 적절한 조치를 취하기 위하여 구조적 안전성 및 결함의 원인 등을 조사・측정・평가하고 보수・보강 등의 방법을 제시함으로써 재해 및 재난을 예방하고 시설물의 효용증진과 공공의 안전을 확보하는데 그 목적이 있다.
B66: 제2조(점검의 범위) 정기안전점검의 범위는 다음과 같다.
...
