Workbook
Name _1.전기공사: #REF!
Name _1.전기공사: #REF!
Name _A100000: #REF!
Name _A100000: #REF!
Name _A66000: #REF!
Name _A66000: #REF!
Name _A67000: #REF!
Name _A67000: #REF!
Name _A68000: #REF!
Name _A68000: #REF!
Name _A80000: #REF!
Name _A80000: #REF!
Name _zz1: #REF!
Name _zz1: #REF!
Name 가맹: #REF!
Name 가맹: #REF!
Name 가설공: #REF!
Name 가설공: #REF!
Name 가시설: #REF!
Name 가시설: #REF!
Name 감사..: #REF!
Name 감사..: #REF!
Name 갑지: #REF!
Name 갑지: #REF!
Name 건물용도: #REF!
Name 건물용도: #REF!
Name 건축: #REF!
Name 건축: #REF!
Name 경과년수: #REF!
Name 계측기: #REF!,#REF!
Name 고급: #REF!
Name 고급: #REF!
Name 고케: 70455
Name 공사명: #REF!
Name 공사명: #REF!
Name 공정수량: #REF!
Name 공정수량: #REF!
Name 공정집계: #REF!
Name 공정집계: #REF!
Name 공조실급수2: #REF!
Name 공조실급수2: #REF!
Name 구구일일: #REF!
Name 구조방식: #REF!
Name 구조방식: #REF!
Name 구조형식: #REF!
Name 구조형식: #REF!
Name 근린합계: #REF!
Name 근린합계: #REF!
Name 기술료: #REF!
Name 기술료: #REF!
Name 기술사: #REF!
Name 기술사: #REF!
Name 기초대가: #REF!
Name 기초대가: #REF!
Name 내선: 49296
Name 내업: #REF!
Name 내업: #REF!
Name 내역: #REF!
Name 내역: #REF!
Name 내역111111111111111: #REF!

Sheet 갑지
G1: ㈜ 에 이 앤 비
G3: (우)16910 경기도 용인시 기흥구 마북로 159 한성프라자 207호 (마북동) 전화 : 031-283-3328 팩스 : 031-284-3328
G6: 문서번호 : | K6: ANB-20260105-13
G7: 작성일자 : | K7: 2026년 01월 05일
G8: 수 신 : | K8: 마곡엠밸리4단지아파트
G9: 참 조 : | K9: 관리소장님
G10: 제 목 : | K10: 마곡엠밸리4단지아파트
G13: 1. 귀 사의 무궁한 발전을 기원합니다.
G15: 2. 당 사는 경기도 용인시 기흥구 마북로 159, 한성프라자 207호에 위치한 업체
G16: 로 시설물 안전진단(구조 안전진단), 안전점검(정밀, 정기), 건축물 하자 조사(점검), 장기수
G17: 선계획 조정(검토 포함) , 시설물 유지보수(도장, 방수공사 등), 기술자문 및 감리 등을 주 업
G18: 무로 하는 ㈜에이앤비입니다.
G20: 3. 그 동안 귀사에서 물심양면으로 도와주신 부분에 대하여 무궁한 감사 드리며,
G21: 귀 아파트에서 수립하고자 하는 장기수선계획서 작성에 관한 견적서를 아래와 같이 제출하
G22: 오니 검토하시어 수립 대행업무 위임하여 주시기 바랍니다.
F24: 4. 시설물 개요 | G24: 4. 시설물 개요
K25: 가. 단 지 명 : | R25: =K10 -> 마곡엠밸리4단지아파트
K26: 나. 소 재 지 : | R26: 서울 성북구 길음로9길 50 (길음동)
K27: 다. 단 지 규 모 : | R27: 아파트 15개동 1012세대
K28: 라. 준 공 일 : | R28: 2010년 09월
K29: 마. 전화/팩스 번호 : | R29: 02-912-5002 | Y29: / | AA29: 02-912-5002
F31: 5. 용 역 범 위 : | G31: 5. 용 역 범 위 :
K32: 가. 공동주택관리법 제29조에 의거한 장기수선계획 검토·조정
K33: 나. 장기수선계획 보고서(1부) 및 엑셀파일 출력물 제공
F35: 6. 용 역 비 : | G35: 6. 용 역 비 : | R35: =대가산출!I3 -> 일금육십만원정 (₩600,000) - VAT별도
G37: 7. 참 고 사 항
K38: 가. 장기수선계획 용역기간 : 6개월 (계약일자로부터)
K39: 나. 이 견적서의 유효기간은 30일 입니다.
G43: ※ 첨 부 : 1. 장기수선계획서 조정 견적서 1부 끝.
G45: ㈜에이앤비 대표이사

Sheet 대가산출
G1: 장기수선계획서 조정 용역
G3: 총 용 역 비 | I3: ="일금"&NUMBERSTRING(M24,1)&"원정 (₩"&TEXT(M24,"#,##0")&") - VAT별도" -> 일금육십만원정 (₩600,000) - VAT별도
G4: 공급가액 | I4: ="일금 "&NUMBERSTRING(M24,1)&"원정"&TEXT(M24,"(￦ #,##0)")&" " -> 일금 육십만원정(₩ 600,000)
G5: 부가가치세 | I5: ="일금 "&NUMBERSTRING(M25,1)&"원정"&TEXT(M25,"(￦ #,##0)")&" " -> #VALUE!
G6: 산 출 내 역 서
G7: 구 분 | I7: 기술자등급 | J7: 단 위 | K7: 인 원 | L7: 단 가 | M7: 금 액 | N7: 비 고
G8: 1. 직 접 인 건 비 | M8: =INT(SUM(M9,M10,M11,M12,M13,M14,M15,M16)) -> 546343
H9: 가.외업 | I9: 특급기술자 | J9: 인·일 | K9: 0 | L9: 373353 | M9: =L9*K9 -> 0
I10: 고급기술자 | J10: 인·일 | K10: 0 | L10: 310884 | M10: =L10*K10 -> 0
I11: 중급기술자 | J11: 인·일 | K11: 0 | L11: 295138 | M11: =L11*K11 -> 0
I12: 초급기술자 | J12: 인·일 | K12: 0 | L12: 235459 | M12: =L12*K12 -> 0
H13: 나.내업 | I13: 특급기술자 | J13: 인·일 | K13: 0 | L13: 373353 | M13: =L13*K13 -> 0
I14: 고급기술자 | J14: 인·일 | K14: 1 | L14: 310884 | M14: =L14*K14 -> 310884
I15: 중급기술자 | J15: 인·일 | K15: 0 | L15: 295138 | M15: =L15*K15 -> 0
I16: 초급기술자 | J16: 인·일 | K16: 1 | L16: 235459 | M16: =L16*K16 -> 235459
G17: 2. 제 경 비 | J17: % | K17: 10 | M17: =ROUND(M8*K17%,0) -> 54634 | N17: 직접인건비*10%
G18: 3. 기 술 료 | J18: % | K18: 10 | M18: =ROUND((M8+M17)*K18%,0) -> 60098 | N18: (직접인건비+제경비)*10%
G19: 4. 직 접 경 비
G20: 5. 인 쇄 비 | M20: 10000
G21: 6. 추 가 경 비 | N21: 구조형식,용도,경과년수
G22: 7. 합 계 금 액 | I22: ( 1 + 2 + 3 + 4 + 5 + 6 ) | M22: =(SUM(M8,M17,M18,M19,M20,M21)) -> 671075
G23: 절 삭 금 액 | M23: 71075
G24: 공 급 가 액 | M24: =M22-M23 -> 600000
G25: 부가가치세 | M25: 별도
G26: 견 적 금 액 | M26: =M24 -> 600000 | N26: 부가세 별도
I27: ㈜ 에 이 앤 비
I28: 사업자등록번호 : 863-87-00907 | N28: ※ 특이사항
I29: 경기도 용인시 기흥구 마북로 159 (한성프라자 207호) | N29: 견적서 유효기간
I30: 대 표 이 사 서 응 원 (인) | N30: 발행일로부터
I31: 전화번호 : 031-283-3328 담당자 : 이 현 희 실장 | N31: 30일입니다.

Sheet 계약서1
B7: 사우
B8: 장기수선계획서 조정 계약서
B9: =갑지!K8 -> 마곡엠밸리4단지아파트
B16: 2026년
I23: ㈜ 에이앤비
I24: 경기도 용인시 기흥구 마북로 159 한성프라자 207호
I25: 전화 : 031-283-3328 팩스 :031-284-3328
B28: 장기수선계획서 조정 계약서
B29: 계 약 자 | D29: 관 리 주 체 | G29: =B9 -> 마곡엠밸리4단지아파트
D30: 계약상대자 | G30: ● 상호또는법인명 : (주)에이앤비
G31: ● 사업자등록번호 : 863-87-00907
G32: ● 주 소 : 경기도 용인시 기흥구 마북로 159 한성프라자 207호
G33: ● 전화번호 : 031-283-3328 팩스번호 : 031-284-3328
G34: ● 대 표 자 : 서 응 원
B35: 계 약 내 용 | D35: 계 약 건 명 | G35: =G29 -> 마곡엠밸리4단지아파트 | M35: 장기수선계획 조정
D36: 계 약 금 액 | G36: =대가산출!I3 -> 일금육십만원정 (₩600,000) - VAT별도
D37: 공 급 가 액 | G37: =대가산출!I3 -> 일금육십만원정 (₩600,000) - VAT별도
D38: 부가 가치세 | G38: 10% 별도
D39: 계약 기간 | G39: 2026 . . . ~ 2026 . . .
D40: 위 치 | G40: =갑지!R26 -> 서울 성북구 길음로9길 50 (길음동)
G41: 전화 : | I41: 031-657-6579 | N41: / | O41: 팩스 : | Q41: 031-656-6579
D42: 보고서 납품 | G42: 계약일로 부터 60일 이내이며 보고서 1부
D43: 기 타 사 항
B45: 관리주체와 계약상대자는 상호 대등한 입장에서 붙임의 계약문서에 의하여 위와 같이 계약을 체결하고 신의에 따라 성실히 계약상의 의무를 이행할 것을 확약하며, 이 계약의 증거로서 계약서를 작성하여 당사자가 기명날인한 후 각각 1통씩 보관한다.
B47: 붙 임 서 류 : | G47: 1. 장기수선계획서 조정 계약서 1부.
B51: 계 약 일 자 : | G51: 2026년 월 일
B52: 관 리 주 체(발 주 자) | L52: 계 약 상 대 자(수 주 자)
B53: 상 호 : | F53: =G29 -> 마곡엠밸리4단지아파트 | L53: 상 호 : | P53: ㈜ 에 이 앤 비
B54: 주 소 : | F54: =G40 -> 서울 성북구 길음로9길 50 (길음동) | L54: 주 소 : | P54: 경기도 용인시 기흥구 마북로 159 한성프라자 207호
B55: 대표회의 회장 : | K55: (인) | L55: 대표이사 : | P55: 서 응 원 | U55: (인)
B56: <붙임 1>
B57: 장기수선계획서 조정 계약조건
B59: 「공동주택관리법」(이하 “공주법”이라 한다) 제29조(장기수선계획), 시행령 제30조
B60: (장기수선계획의 수립), 시행규칙 제7조(장기수선계획의 수립기준 등)의 규정에 따라
B61: =F53 -> 마곡엠밸리4단지아파트 | I61: (이하 "발주자"라 한다)와 장기수선계획 조정 대행자인
B62: ㈜ 에이앤비 (이하 "수주자"라 한다)는 다음과같이 계약을 체결한다.
B64: 제1조(목적)
C65: 본 계약은 "발주자"가 관리하고 있는 시설물에 대하여 "발주자"는 시설물에 대한 공동주택관리법 제29조(장기수선계획)의 규정에 따라 장기적으로 주요시설을 보수하거나 교체하는데 필요한 계획의 재수립(수량 및 물량 적산)에 관한 장기수선 계획서 업무를 "수주자"에게 위임하고 "수주자"는 아파트의 장기수선계획서의 작성 조정 대행을 성실히 수행하는 것을 원칙으로 한다.
B67: 제2조(용역의 범위)
C68: ① 조정
...
